<?xml version="1.0"?>
<robot xmlns:xacro="http://www.ros.org/wiki/xacro" name="hopper">

  <xacro:macro name="sphere_inertial_with_origin" params="radius mass *origin">
    <inertial>
      <mass value="${mass}" />
      <xacro:insert_block name="origin" />
      <inertia ixx="${0.4 * mass * radius * radius}" ixy="0.0" ixz="0.0"
        iyy="${0.4 * mass * radius * radius}" iyz="0.0"
        izz="${0.4 * mass * radius * radius}" />
    </inertial>
  </xacro:macro>

  <xacro:macro name="sphere_with_origin" params="radius mass color *origin">
    <visual>
            <geometry>
                <sphere  radius="${radius}"/>
            </geometry>
            <xacro:insert_block name="origin" />
            <material name="${color}"/>
    </visual>

    <collision>
          <geometry>
                <sphere  radius="${radius}"/>
          </geometry>
          <xacro:insert_block name="origin" />
    </collision>

    <inertial>
      <mass value="${mass}" />
      <xacro:insert_block name="origin" />
      <inertia ixx="${0.4 * mass * radius * radius}" ixy="0.0" ixz="0.0"
        iyy="${0.4 * mass * radius * radius}" iyz="0.0"
        izz="${0.4 * mass * radius * radius}" />
    </inertial>
  </xacro:macro>

  <xacro:macro name="cylinder_inertial_with_origin" params="radius length mass *origin">
    <inertial>
      <mass value="${mass}" />
      <xacro:insert_block name="origin" />
      <inertia ixx="${0.0833333 * mass * (3 * radius * radius + length * length)}" ixy="0.0" ixz="0.0"
        iyy="${0.0833333 * mass * (3 * radius * radius + length * length)}" iyz="0.0"
        izz="${0.5 * mass * radius * radius}" />
    </inertial>
  </xacro:macro>

  <xacro:macro name="cylinder_with_origin" params="radius length mass color *origin">
     <visual>
            <geometry>
                <cylinder length="${length}" radius="${radius}"/>

            </geometry>
            <xacro:insert_block name="origin" />
            <material name="${color}"/>
     </visual>

     <collision>
            <geometry>
                <cylinder length="${length}" radius="${radius}"/>

            </geometry>
            <xacro:insert_block name="origin" />
     </collision>
    <inertial>
      <mass value="${mass}" />
      <xacro:insert_block name="origin" />
      <inertia ixx="${0.0833333 * mass * (3 * radius * radius + length * length)}" ixy="0.0" ixz="0.0"
        iyy="${0.0833333 * mass * (3 * radius * radius + length * length)}" iyz="0.0"
        izz="${0.5 * mass * radius * radius}" />
    </inertial>
  </xacro:macro>

  <xacro:macro name="box_inertial_with_origin" params="x y z mass *origin">
    <inertial>
      <mass value="${mass}" />
      <xacro:insert_block name="origin" />
      <inertia ixx="${0.0833333 * mass * (y*y + z*z)}" ixy="0.0" ixz="0.0"
        iyy="${0.0833333 * mass * (x*x + z*z)}" iyz="0.0"
        izz="${0.0833333 * mass * (x*x + y*y)}" />
    </inertial>
  </xacro:macro>

  <xacro:macro name="box_with_origin" params="x y z mass color *origin">
    <visual>
            <geometry>
                <box size="${x} ${y} ${z}"/>
            </geometry>
            <xacro:insert_block name="origin" />
             <material name="${color}"/>
    </visual>

    <collision>
        <geometry>
                <box size="${x} ${y} ${z}"/>
        </geometry>
        <xacro:insert_block name="origin" />
    </collision>

    <inertial>
      <mass value="${mass}" />
      <xacro:insert_block name="origin" />
      <inertia ixx="${0.0833333 * mass * (y*y + z*z)}" ixy="0.0" ixz="0.0"
        iyy="${0.0833333 * mass * (x*x + z*z)}" iyz="0.0"
        izz="${0.0833333 * mass * (x*x + y*y)}" />
    </inertial>
  </xacro:macro>

    <material name="black">
        <color rgba="0.3 0 0 0.7"/>
    </material>
    <material name="blue">
        <color rgba="0.6 0.7 0.8 0.7"/>
    </material>

        <material name="yellow">
        <color rgba="0.3 0.3 0 0.7"/>
    </material>

    <!-- Base Frame of Hopper -->


    <link name="base_link1">
        <xacro:box_with_origin x="0.2" y="0.01" z="0.01" mass="0.15" color="yellow">
            <origin xyz="0 0.095 0"/>
        </xacro:box_with_origin>
    </link>

    <link name="base_link2">
        <xacro:box_with_origin x="0.2" y="0.01" z="0.01" mass="0.15" color="blue">
            <origin xyz="0 -0.095 0"/>
        </xacro:box_with_origin>
    </link>

    <joint name="base1_to_base2" type="fixed">
        <parent link="base_link1"/>
        <child link="base_link2"/>
    </joint>

    <link name="base_link3">
        <xacro:box_with_origin x="0.01" y="0.18" z="0.01" mass="0.15" color="blue">
            <origin xyz="0.095 0 0"/>
        </xacro:box_with_origin>
    </link>

    <joint name="base1_to_base3" type="fixed">
        <parent link="base_link1"/>
        <child link="base_link3"/>
    </joint>

    <link name="base_link4">
        <xacro:box_with_origin x="0.01" y="0.18" z="0.01" mass="0.15" color="blue">
            <origin xyz="-0.095 0 0"/>
        </xacro:box_with_origin>
    </link>


    <joint name="base1_to_base4" type="fixed">
        <parent link="base_link1"/>
        <child link="base_link4"/>
    </joint>


     <!-- Mid Frame of Hopper -->

    <link name="mid_link1">
        <xacro:box_with_origin x="0.01" y="0.03" z="0.01" mass="0.15" color="black">
            <origin xyz="0.085 0 0"/>
        </xacro:box_with_origin>
    </link>

     <joint name="base_mid_joint" type="revolute">
        <axis xyz="-1 0 0"/>
        <limit effort="1000.0" lower="-0.548" upper="0.548" velocity="5"/>
        <origin rpy="0 0 0" xyz="0 0 0"/>
        <parent link="base_link3"/>
        <child link="mid_link1"/>
    </joint>

    <link name="mid_link2">
        <xacro:box_with_origin x="0.01" y="0.03" z="0.01" mass="0.15" color="black">
            <origin xyz="-0.085 0 0"/>
        </xacro:box_with_origin>
    </link>

     <joint name="mid1_mid2_joint" type="fixed">
        <parent link="mid_link1"/>
        <child link="mid_link2"/>
    </joint>

    <link name="mid_link3">
        <xacro:box_with_origin x="0.18" y="0.01" z="0.01" mass="0.15" color="black">
            <origin xyz="0 0.02 0"/>
        </xacro:box_with_origin>
    </link>

     <joint name="mid1_mid3_joint" type="fixed">
        <parent link="mid_link1"/>
        <child link="mid_link3"/>
    </joint>

    <link name="mid_link4">
        <xacro:box_with_origin x="0.18" y="0.01" z="0.01" mass="0.15" color="black">
            <origin xyz="0 -0.02 0"/>
        </xacro:box_with_origin>
    </link>

     <joint name="mid1_mid4_joint" type="fixed">
        <parent link="mid_link1"/>
        <child link="mid_link4"/>
    </joint>


    <link name="cylinder">
        <xacro:cylinder_with_origin radius="0.01" length="0.02" mass="0.1" color="yellow">
            <origin xyz="0 0 0"/>
        </xacro:cylinder_with_origin>
    </link>


    <joint name="mid_cylinder_joint" type="revolute">
        <axis xyz="0 -1 0"/>
        <limit effort="1000.0" lower="-0.548" upper="0.548" velocity="5"/>
        <origin rpy="0 0 0" xyz="0 0 0"/>
        <parent link="mid_link3"/>
        <child link="cylinder"/>
    </joint>


    <link name="leg_tip">
        <xacro:sphere_with_origin radius="0.01" mass="0.02" color="yellow">
            <origin xyz="0 0 0"/>
        </xacro:sphere_with_origin>
    </link>


    <joint name="cylinder_tip_joint" type="prismatic">
        <axis xyz="0 0 1"/>
        <limit effort="1000.0" lower="-0.01" upper="0.075" velocity="0.5"/>
        <origin rpy="0 0 0" xyz="0 0 -0.15"/>
        <parent link="cylinder"/>
        <child link="leg_tip"/>

        <dynamics damping = "5"/>

    </joint>





</robot>